Workbook

Sheet APY
D2: Minimum Guaranteed Pension of Rs. 1000/month | I2: Minimum Guaranteed Pension of Rs.2000/month | N2: Minimum Guaranteed Pension of Rs.3000/month | S2: Minimum Guaranteed Pension of Rs.4000/month | X2: Minimum Guaranteed Pension of Rs.5000/month | AE2: Per Month Income | AF2: Returns
A3: Return of Corpus Amount to the Nominee | D3: Rs. 1.7 Lakh | I3: Rs. 3.4 Lakhs | N3: Rs. 5.1 Lakhs | S3: Rs. 6.8 Lakhs | X3: Rs. 8.5 Lakhs | AE3: 1000 | AF3: =D3 -> Rs. 1.7 Lakh | AH3: =VLOOKUP(Dashboard1!N4,monthly[],2,1) -> Rs. 8.5 Lakhs
D4: 1K Pension Investment | I4: 2K Pension Investment | N4: 3K Pension Investment | S4: 4K Pension Investment | X4: 5K Pension Investment | AE4: 2000 | AF4: =I3 -> Rs. 3.4 Lakhs
A5: Age at entry | B5: Vesting period | D5: Age at entry | E5: Monthly | F5: Quarterly | G5: Half Yearly | I5: Age at entry | J5: Monthly | K5: Quarterly | L5: Half Yearly | N5: Age at entry | O5: Monthly | P5: Quarterly | Q5: Half Yearly | S5: Age at entry | T5: Monthly | U5: Quarterly | V5: Half Yearly | X5: Age at entry | Y5: Monthly | Z5: Quarterly | AA5: Half Yearly | AE5: 3000 | AF5: =N3 -> Rs. 5.1 Lakhs
A6: 18 | B6: 42 | D6: 18 | E6: 42 | F6: 125 | G6: 248 | I6: 18 | J6: 84 | K6: 250 | L6: 496 | N6: 18 | O6: 126 | P6: 376 | Q6: 744 | S6: 18 | T6: 168 | U6: 501 | V6: 991 | X6: 18 | Y6: 210 | Z6: 626 | AA6: 1239 | AE6: 4000 | AF6: =S3 -> Rs. 6.8 Lakhs
A7: 19 | B7: 41 | D7: 19 | E7: 46 | F7: 137 | G7: 271 | I7: 19 | J7: 92 | K7: 274 | L7: 543 | N7: 19 | O7: 138 | P7: 411 | Q7: 814 | S7: 19 | T7: 183 | U7: 545 | V7: 1080 | X7: 19 | Y7: 228 | Z7: 679 | AA7: 1346 | AE7: 5000 | AF7: =X3 -> Rs. 8.5 Lakhs
A8: 20 | B8: 40 | D8: 20 | E8: 50 | F8: 149 | G8: 295 | I8: 20 | J8: 100 | K8: 298 | L8: 590 | N8: 20 | O8: 150 | P8: 447 | Q8: 885 | S8: 20 | T8: 198 | U8: 590 | V8: 1169 | X8: 20 | Y8: 248 | Z8: 739 | AA8: 1464
A9: 21 | B9: 39 | D9: 21 | E9: 54 | F9: 161 | G9: 319 | I9: 21 | J9: 108 | K9: 322 | L9: 637 | N9: 21 | O9: 162 | P9: 483 | Q9: 956 | S9: 21 | T9: 215 | U9: 641 | V9: 1269 | X9: 21 | Y9: 269 | Z9: 802 | AA9: 1588
A10: 22 | B10: 38 | D10: 22 | E10: 59 | F10: 176 | G10: 348 | I10: 22 | J10: 117 | K10: 349 | L10: 690 | N10: 22 | O10: 177 | P10: 527 | Q10: 1046 | S10: 22 | T10: 234 | U10: 697 | V10: 1381 | X10: 22 | Y10: 292 | Z10: 870 | AA10: 1723
A11: 23 | B11: 37 | D11: 23 | E11: 64 | F11: 191 | G11: 378 | I11: 23 | J11: 127 | K11: 378 | L11: 749 | N11: 23 | O11: 192 | P11: 572 | Q11: 1133 | S11: 23 | T11: 254 | U11: 757 | V11: 1499 | X11: 23 | Y11: 318 | Z11: 948 | AA11: 1877
A12: 24 | B12: 36 | D12: 24 | E12: 70 | F12: 209 | G12: 413 | I12: 24 | J12: 139 | K12: 414 | L12: 820 | N12: 24 | O12: 208 | P12: 620 | Q12: 1228 | S12: 24 | T12: 277 | U12: 826 | V12: 1635 | X12: 24 | Y12: 346 | Z12: 1031 | AA12: 2042
A13: 25 | B13: 35 | D13: 25 | E13: 76 | F13: 226 | G13: 449 | I13: 25 | J13: 151 | K13: 450 | L13: 891 | N13: 25 | O13: 226 | P13: 674 | Q13: 1334 | S13: 25 | T13: 301 | U13: 897 | V13: 1776 | X13: 25 | Y13: 376 | Z13: 1121 | AA13: 2219
A14: 26 | B14: 34 | D14: 26 | E14: 82 | F14: 244 | G14: 484 | I14: 26 | J14: 164 | K14: 489 | L14: 968 | N14: 26 | O14: 246 | P14: 733 | Q14: 1452 | S14: 26 | T14: 327 | U14: 975 | V14: 1930 | X14: 26 | Y14: 409 | Z14: 1219 | AA14: 2414
A15: 27 | B15: 33 | D15: 27 | E15: 90 | F15: 268 | G15: 531 | I15: 27 | J15: 178 | K15: 530 | L15: 1050 | N15: 27 | O15: 268 | P15: 799 | Q15: 1582 | S15: 27 | T15: 356 | U15: 1061 | V15: 2101 | X15: 27 | Y15: 446 | Z15: 1329 | AA15: 2632
A16: 28 | B16: 32 | D16: 28 | E16: 97 | F16: 289 | G16: 572 | I16: 28 | J16: 194 | K16: 578 | L16: 1145 | N16: 28 | O16: 292 | P16: 870 | Q16: 1723 | S16: 28 | T16: 388 | U16: 1156 | V16: 2290 | X16: 28 | Y16: 485 | Z16: 1445 | AA16: 2862
A17: 29 | B17: 31 | D17: 29 | E17: 106 | F17: 316 | G17: 626 | I17: 29 | J17: 212 | K17: 632 | L17: 1251 | N17: 29 | O17: 318 | P17: 948 | Q17: 1877 | S17: 29 | T17: 423 | U17: 1261 | V17: 2496 | X17: 29 | Y17: 529 | Z17: 1577 | AA17: 3122
A18: 30 | B18: 30 | D18: 30 | E18: 116 | F18: 346 | G18: 685 | I18: 30 | J18: 231 | K18: 688 | L18: 1363 | N18: 30 | O18: 347 | P18: 1034 | Q18: 2048 | S18: 30 | T18: 462 | U18: 1377 | V18: 2727 | X18: 30 | Y18: 577 | Z18: 1720 | AA18: 3405
A19: 31 | B19: 29 | D19: 31 | E19: 126 | F19: 376 | G19: 744 | I19: 31 | J19: 252 | K19: 751 | L19: 1487 | N19: 31 | O19: 379 | P19: 1129 | Q19: 2237 | S19: 31 | T19: 504 | U19: 1502 | V19: 2974 | X19: 31 | Y19: 630 | Z19: 1878 | AA19: 3718
... A27: 39 | B27: 21 | D27: 39 | E27: 264 | F27: 787 | G27: 1558 | I27: 39 | J27: 528 | K27: 1574 | L27: 3116 | N27: 39 | O27: 792 | P27: 2360 | Q27: 4674 | S27: 39 | T27: 1054 | U27: 3141 | V27: 6220 | X27: 39 | Y27: 1318 | Z27: 3928 | AA27: 7778
A29: invest year | B29: =VLOOKUP(Dashboard1!J4,Age[],2,1) -> 32 | E29: =VLOOKUP(Dashboard1!$J$4,one[],2,1) -> 97 | F29: =VLOOKUP(Dashboard1!$J$4,one[],3,1) -> 289 | G29: =VLOOKUP(Dashboard1!$J$4,one[],4,1) -> 572 | J29: =VLOOKUP(Dashboard1!$J$4,two[],2,1) -> 194 | K29: =VLOOKUP(Dashboard1!$J$4,two[],3,1) -> 578 | L29: =VLOOKUP(Dashboard1!$J$4,two[],4,1) -> 1145 | O29: =VLOOKUP(Dashboard1!$J$4,three[],2,1) -> 292 | P29: =VLOOKUP(Dashboard1!$J$4,three[],3,1) -> 870 | Q29: =VLOOKUP(Dashboard1!$J$4,three[],4,1) -> 1723 | T29: =VLOOKUP(Dashboard1!$J$4,four[],2,1) -> 388 | U29: =VLOOKUP(Dashboard1!$J$4,four[],3,1) -> 1156 | V29: =VLOOKUP(Dashboard1!$J$4,four[],4,1) -> 2290 | Y29: =VLOOKUP(Dashboard1!$J$4,five[],2,1) -> 485 | Z29: =VLOOKUP(Dashboard1!$J$4,five[],3,1) -> 1445 | AA29: =VLOOKUP(Dashboard1!$J$4,five[],4,1) -> 2862
E32: Monthly | F32: Quarterly | G32: Half Yearly
E33: =IF(Dashboard1!N4=1000,APY!E29,IF(Dashboard1!N4=2000,APY!J29,IF(Dashboard1!N4=3000,APY!O29,IF(Dashboard1!N4=4000,APY!T29,APY!Y29)))) -> 485 | F33: =IF(Dashboard1!N4=1000,APY!F29,IF(Dashboard1!N4=2000,APY!K29,IF(Dashboard1!N4=3000,APY!P29,IF(Dashboard1!N4=4000,APY!U29,APY!Z29)))) -> 1445 | G33: =IF(Dashboard1!N4=1000,APY!G29,IF(Dashboard1!N4=2000,APY!L29,IF(Dashboard1!N4=3000,APY!Q29,IF(Dashboard1!N4=4000,APY!V29,APY!AA29)))) -> 2862
D35: Total Invest | E35: =(E33*12)*$B$29 -> 186240 | F35: =(F33*4)*$B$29 -> 184960 | G35: =(G33*2)*$B$29 -> 183168
D36: Year Invest | E36: =E33*12 -> 5820 | F36: =F33*4 -> 5780 | G36: =G33*2 -> 5724
E39: =ROUND(MIN(E35:G35)/Dashboard1!$N$4,0) -> 37

Sheet Dashboard1
J2: Age to Invest | N2: Monthly Pension
J4: 28 | N4: 5000

Sheet Dashboard2

Sheet Sheet1
A1: Birth Date | B1: 35057 | D1: Start Date | E1: End Date | M1: Total Invested | N1: =N9 -> 85486
A2: Todays Date | B2: =TODAY() -> 46058 | D2: 44866 | E2: =D2+(B4*365) -> 55816 | G2: YES | H2: NO | M2: Total Pending | N2: =MAX(APY!E35:G35)-N1 -> 100754 | Q2: 1000 | R2: 170000
A3: Age | B3: =DATEDIF(B1,B2,"y") -> 30 | Q3: 2000 | R3: 340000
A4: Invest in Years | B4: =VLOOKUP(B3,Age[],2,1) -> 30 | D4: Monthly Income Expect | Q4: 3000 | R4: 510000
A5: Total Age | B5: =B3+B4 -> 60 | D5: =Dashboard1!N4 -> 5000 | E5: =VLOOKUP(D5,Q2:R6,2,1) -> 850000 | Q5: 4000 | R5: 680000
Q6: 5000 | R6: 850000
A7: Invested | B7: Prnding | E7: Invested | F7: Prnding | I7: Invested | J7: Prnding
A8: =C9*B10 -> 1731 | B8: =APY!E35-Sheet1!A8 -> 184509 | C8: =COUNTIF($C$10:$C$2958,"NO") -> 2946 | E8: =G9*F10 -> 32680 | F8: =APY!F35-Sheet1!E8 -> 152280 | G8: =COUNTIF($G$10:$G$2958,"NO") -> 157 | I8: =K9*J10 -> 51075 | J8: =APY!G35-Sheet1!I8 -> 132093 | K8: =COUNTIF($K$10:$K$2958,"NO") -> 73 | M8: Invested Amount | P8: Contribution
A9: Monthly Invest | C9: =COUNTIF($C$10:$C$2958,"YES") -> 3 | E9: Quarterly Invest | G9: =COUNTIF($G$10:$G$2958,"YES") -> 19 | I9: Half Yearly Incest | K9: =COUNTIF($K$10:$K$2958,"YES") -> 15 | M9: Total Invested | N9: =A8+E8+I8 -> 85486 | P9: Monthly | Q9: Quarterly | R9: Half Yearly
A10: =D2 -> 44866 | B10: =IF($D$5=1000,VLOOKUP($B$3,one[],2,1),IF($D$5=2000,VLOOKUP($B$3,two[],2,1),IF($D$5=3000,VLOOKUP($B$3,three[],2,1),IF($D$5=4000,VLOOKUP($B$3,four[],2,1),VLOOKUP($B$3,five[],2,1))))) -> 577 | C10: YES | E10: =D2 -> 44866 | F10: =IF($D$5=1000,VLOOKUP($B$3,one[],3,1),IF($D$5=2000,VLOOKUP($B$3,two[],3,1),IF($D$5=3000,VLOOKUP($B$3,three[],3,1),IF($D$5=4000,VLOOKUP($B$3,four[],3,1),VLOOKUP($B$3,five[],3,1))))) -> 1720 | G10: NO | I10: =D2 -> 44866 | J10: =IF($D$5=1000,VLOOKUP($B$3,one[],4,1),IF($D$5=2000,VLOOKUP($B$3,two[],4,1),IF($D$5=3000,VLOOKUP($B$3,three[],4,1),IF($D$5=4000,VLOOKUP($B$3,four[],4,1),VLOOKUP($B$3,five[],4,1))))) -> 3405 | K10: NO | M10: Total Corpus | N10: =E5 -> 850000 | P10: =A8 -> 1731 | Q10: =E8 -> 32680 | R10: =I8 -> 51075
A11: =A10+30 -> 44896 | B11: =B10 -> 577 | C11: YES | E11: =E10+90 -> 44956 | F11: =F10 -> 1720 | G11: YES | I11: =I10+180 -> 45046 | J11: =J10 -> 3405 | K11: NO
A12: =A11+30 -> 44926 | B12: =B11 -> 577 | C12: YES | E12: =E11+90 -> 45046 | F12: =F11 -> 1720 | G12: YES | I12: =I11+180 -> 45226 | J12: =J11 -> 3405 | K12: NO | M12: Total Years Contributed
A13: =A12+30 -> 44956 | B13: =B12 -> 577 | C13: NO | E13: =E12+90 -> 45136 | F13: =F12 -> 1720 | G13: YES | I13: =I12+180 -> 45406 | J13: =J12 -> 3405 | K13: NO | M13: Monthly | N13: =C9/12 -> 0.25
A14: =A13+30 -> 44986 | B14: =B13 -> 577 | C14: NO | E14: =E13+90 -> 45226 | F14: =F13 -> 1720 | G14: YES | I14: =I13+180 -> 45586 | J14: =J13 -> 3405 | K14: NO | M14: Quarterly | N14: =G9/4 -> 4.75
A15: =A14+30 -> 45016 | B15: =B14 -> 577 | C15: NO | E15: =E14+90 -> 45316 | F15: =F14 -> 1720 | G15: YES | I15: =I14+180 -> 45766 | J15: =J14 -> 3405 | K15: YES | M15: Half Yearly | N15: =K9/2 -> 7.5
A16: =A15+30 -> 45046 | B16: =B15 -> 577 | C16: NO | E16: =E15+90 -> 45406 | F16: =F15 -> 1720 | G16: YES | I16: =I15+180 -> 45946 | J16: =J15 -> 3405 | K16: YES | M16: Invested Years | N16: =SUM(N13:N15) -> 12.5
A17: =A16+30 -> 45076 | B17: =B16 -> 577 | C17: NO | E17: =E16+90 -> 45496 | F17: =F16 -> 1720 | G17: YES | I17: =I16+180 -> 46126 | J17: =J16 -> 3405 | K17: YES | M17: Remain Years | N17: =B4-N16 -> 17.5
A18: =A17+30 -> 45106 | B18: =B17 -> 577 | C18: NO | E18: =E17+90 -> 45586 | F18: =F17 -> 1720 | G18: YES | I18: =I17+180 -> 46306 | J18: =J17 -> 3405 | K18: YES
A19: =A18+30 -> 45136 | B19: =B18 -> 577 | C19: NO | E19: =E18+90 -> 45676 | F19: =F18 -> 1720 | G19: YES | I19: =I18+180 -> 46486 | J19: =J18 -> 3405 | K19: YES
A20: =A19+30 -> 45166 | B20: =B19 -> 577 | C20: NO | E20: =E19+90 -> 45766 | F20: =F19 -> 1720 | G20: NO | I20: =I19+180 -> 46666 | J20: =J19 -> 3405 | K20: YES
A21: =A20+30 -> 45196 | B21: =B20 -> 577 | C21: NO | E21: =E20+90 -> 45856 | F21: =F20 -> 1720 | G21: NO | I21: =I20+180 -> 46846 | J21: =J20 -> 3405 | K21: YES
A22: =A21+30 -> 45226 | B22: =B21 -> 577 | C22: NO | E22: =E21+90 -> 45946 | F22: =F21 -> 1720 | G22: NO | I22: =I21+180 -> 47026 | J22: =J21 -> 3405 | K22: YES
A23: =A22+30 -> 45256 | B23: =B22 -> 577 | C23: NO | E23: =E22+90 -> 46036 | F23: =F22 -> 1720 | G23: NO | I23: =I22+180 -> 47206 | J23: =J22 -> 3405 | K23: YES
A24: =A23+30 -> 45286 | B24: =B23 -> 577 | C24: NO | E24: =E23+90 -> 46126 | F24: =F23 -> 1720 | G24: NO | I24: =I23+180 -> 47386 | J24: =J23 -> 3405 | K24: YES
A25: =A24+30 -> 45316 | B25: =B24 -> 577 | C25: NO | E25: =E24+90 -> 46216 | F25: =F24 -> 1720 | G25: NO | I25: =I24+180 -> 47566 | J25: =J24 -> 3405 | K25: YES
A26: =A25+30 -> 45346 | B26: =B25 -> 577 | C26: NO | E26: =E25+90 -> 46306 | F26: =F25 -> 1720 | G26: NO | I26: =I25+180 -> 47746 | J26: =J25 -> 3405 | K26: YES
A27: =A26+30 -> 45376 | B27: =B26 -> 577 | C27: NO | E27: =E26+90 -> 46396 | F27: =F26 -> 1720 | G27: NO | I27: =I26+180 -> 47926 | J27: =J26 -> 3405 | K27: YES
A28: =A27+30 -> 45406 | B28: =B27 -> 577 | C28: NO | E28: =E27+90 -> 46486 | F28: =F27 -> 1720 | G28: NO | I28: =I27+180 -> 48106 | J28: =J27 -> 3405 | K28: YES
A29: =A28+30 -> 45436 | B29: =B28 -> 577 | C29: NO | E29: =E28+90 -> 46576 | F29: =F28 -> 1720 | G29: NO | I29: =I28+180 -> 48286 | J29: =J28 -> 3405 | K29: YES
... A97: =A96+30 -> 47476 | B97: =B96 -> 577 | C97: NO | E97: =E96+90 -> 52696 | F97: =F96 -> 1720 | G97: NO | I97: =I96+180 -> 60526 | J97: =J96 -> 3405 | K97: NO
A98: =A97+30 -> 47506 | B98: =B97 -> 577 | C98: NO | E98: =E97+90 -> 52786 | F98: =F97 -> 1720 | G98: NO
A99: =A98+30 -> 47536 | B99: =B98 -> 577 | C99: NO | E99: =E98+90 -> 52876 | F99: =F98 -> 1720 | G99: NO
A100: =A99+30 -> 47566 | B100: =B99 -> 577 | C100: NO | E100: =E99+90 -> 52966 | F100: =F99 -> 1720 | G100: NO
A101: =A100+30 -> 47596 | B101: =B100 -> 577 | C101: NO | E101: =E100+90 -> 53056 | F101: =F100 -> 1720 | G101: NO
A102: =A101+30 -> 47626 | B102: =B101 -> 577 | C102: NO | E102: =E101+90 -> 53146 | F102: =F101 -> 1720 | G102: NO
A103: =A102+30 -> 47656 | B103: =B102 -> 577 | C103: NO | E103: =E102+90 -> 53236 | F103: =F102 -> 1720 | G103: NO
A104: =A103+30 -> 47686 | B104: =B103 -> 577 | C104: NO | E104: =E103+90 -> 53326 | F104: =F103 -> 1720 | G104: NO
A105: =A104+30 -> 47716 | B105: =B104 -> 577 | C105: NO | E105: =E104+90 -> 53416 | F105: =F104 -> 1720 | G105: NO
A106: =A105+30 -> 47746 | B106: =B105 -> 577 | C106: NO | E106: =E105+90 -> 53506 | F106: =F105 -> 1720 | G106: NO
A107: =A106+30 -> 47776 | B107: =B106 -> 577 | C107: NO | E107: =E106+90 -> 53596 | F107: =F106 -> 1720 | G107: NO
...
